Workbook
Name row_filter: #REF!

Sheet Instructions
A1: Please make a copy of this sheet: File -> Make a Copy (Must be logged in to Google / We do not grant edit access)
A2: SEASON 5 BETA
A3: How this sheet works
A4: Edit this sheet by going to File → Make a copy. If the sheet says it is outdated, simply head over to the resources channel and make a new copy.
A5: Our benchmarks are divided in 3 levels: Novice, Intermediate and Advanced
A6: New players should play the Novice benchmarks
A7: Guideline: Aspiring Platinum players are recommended to achieve Gold on Novice to be able to move on to the Intermediate benchmarks
A8: Guideline: Aspiring Grandmaster players are recommended to achieve Master on Intermediate to be able to move on to the Advanced benchmarks
A9: In order to receive a rank you need to set a score on a scenario from each of the nine subcategories (Dynamic, Static, Linear, Precise, Reactive, Control, Speed, Evasive, and Stability)
A10: Only your highest score in a subcategory will count towards your rank
A11: Your overall energy is an average of your subcategory energy, with lower scores weighted more heavily (harmonic mean)
A12: Pushing your score further to the next rank target awards more energy
... A15: The chart below shows the energy required for each rank
A16: Difficulty | B16: Click to navigate to the Novice Benchmarks | F16: Click to navigate to the Intermediate Benchmarks | J16: Click to navigate to the Advanced Benchmarks
B17: Novice | F17: Intermediate | J17: Advanced
A18: Rank Name | B18: =IFERROR(__xludf.DUMMYFUNCTION("importrange(""https://docs.google.com/spreadsheets/d/1QpiWrPmnZBx1RuofZtIGCS-oMK8ehqXWzsSoP8Mi0_8"", ""Benchmarks!E3:H4"")"),"Iron") -> Iron | C18: =IFERROR(__xludf.DUMMYFUNCTION("""COMPUTED_VALUE"""),"Bronze") -> Bronze | D18: =IFERROR(__xludf.DUMMYFUNCTION("""COMPUTED_VALUE"""),"Silver") -> Silver | E18: =IFERROR(__xludf.DUMMYFUNCTION("""COMPUTED_VALUE"""),"Gold") -> Gold | F18: =IFERROR(__xludf.DUMMYFUNCTION("importrange(""https://docs.google.com/spreadsheets/d/1QpiWrPmnZBx1RuofZtIGCS-oMK8ehqXWzsSoP8Mi0_8"", ""Benchmarks!M3:P4"")"),"Platinum") -> Platinum | G18: =IFERROR(__xludf.DUMMYFUNCTION("""COMPUTED_VALUE"""),"Diamond") -> Diamond | H18: =IFERROR(__xludf.DUMMYFUNCTION("""COMPUTED_VALUE"""),"Jade") -> Jade | I18: =IFERROR(__xludf.DUMMYFUNCTION("""COMPUTED_VALUE"""),"Master") -> Master | J18: =IFERROR(__xludf.DUMMYFUNCTION("importrange(""https://docs.google.com/spreadsheets/d/1QpiWrPmnZBx1RuofZtIGCS-oMK8ehqXWzsSoP8Mi0_8"", ""Benchmarks!U3:X4"")"),"Grandmaster") -> Grandmaster | K18: =IFERROR(__xludf.DUMMYFUNCTION("""COMPUTED_VALUE"""),"Nova") -> Nova | L18: =IFERROR(__xludf.DUMMYFUNCTION("""COMPUTED_VALUE"""),"Astra") -> Astra | M18: =IFERROR(__xludf.DUMMYFUNCTION("""COMPUTED_VALUE"""),"Celestial") -> Celestial
A19: Energy Threshold | B19: =IFERROR(__xludf.DUMMYFUNCTION("""COMPUTED_VALUE"""),100.0) -> 100 | C19: =IFERROR(__xludf.DUMMYFUNCTION("""COMPUTED_VALUE"""),200.0) -> 200 | D19: =IFERROR(__xludf.DUMMYFUNCTION("""COMPUTED_VALUE"""),300.0) -> 300 | E19: =IFERROR(__xludf.DUMMYFUNCTION("""COMPUTED_VALUE"""),400.0) -> 400 | F19: =IFERROR(__xludf.DUMMYFUNCTION("""COMPUTED_VALUE"""),500.0) -> 500 | G19: =IFERROR(__xludf.DUMMYFUNCTION("""COMPUTED_VALUE"""),600.0) -> 600 | H19: =IFERROR(__xludf.DUMMYFUNCTION("""COMPUTED_VALUE"""),700.0) -> 700 | I19: =IFERROR(__xludf.DUMMYFUNCTION("""COMPUTED_VALUE"""),800.0) -> 800 | J19: =IFERROR(__xludf.DUMMYFUNCTION("""COMPUTED_VALUE"""),900.0) -> 900 | K19: =IFERROR(__xludf.DUMMYFUNCTION("""COMPUTED_VALUE"""),1000.0) -> 1000 | L19: =IFERROR(__xludf.DUMMYFUNCTION("""COMPUTED_VALUE"""),1100.0) -> 1100 | M19: =IFERROR(__xludf.DUMMYFUNCTION("""COMPUTED_VALUE"""),1200.0) -> 1200
A20: =IFERROR(__xludf.DUMMYFUNCTION("if(importrange(""https://docs.google.com/spreadsheets/d/1JxRnDKurkxZO94D2V46kmGWozPF7dbOpsMfWZL85LvU"", ""Changelog!A2:A2"")=indirect(""Changelog!A2""), concatenate(""Sheet Version: "", Changelog!A2), hyperlink(""https://docs.google.com/spreadsheets/d/1Jx"&"RnDKurkxZO94D2V46kmGWozPF7dbOpsMfWZL85LvU"", ""Outdated version, click link & make a new copy!""))"),"Sheet Version: 1.0.7") -> Sheet Version: 1.0.7
A21: Socials | B21: =HYPERLINK("https://voltaic.gg/", "Website↗") -> Website↗ | D21: =HYPERLINK("http://discord.gg/voltaic","Discord↗") -> Discord↗ | F21: Twitter↗ | H21: YouTube↗ | J21: =HYPERLINK("","Guide↗") -> Guide↗ | L21: =HYPERLINK("https://docs.google.com/document/d/1omExq_y4ld9vkvbTFkLdjlT5UwQpvYSgyk5PgA7nrzM/edit?usp=sharing","Rules↗") -> Rules↗

Sheet Novice
A1: Voltaic KvKs Novice Benchmarks S5 BETA | E1: {=concatenate(choose(match(H2, {0, M2:P2}), "Unranked", M1, N1, O1, P1), if(and(F3:F20 >= choose(match(H2, {0, M2:P2}), 1E+99, M3:M20, N3:N20, O3:O20, P3:P20)), " Complete", ""))} -> Unranked | H1: Energy | M1: =IFERROR(__xludf.DUMMYFUNCTION("importrange(""https://docs.google.com/spreadsheets/d/1JxRnDKurkxZO94D2V46kmGWozPF7dbOpsMfWZL85LvU"", ""Novice!M1:P20"")"),"Iron") -> Iron | N1: =IFERROR(__xludf.DUMMYFUNCTION("""COMPUTED_VALUE"""),"Bronze") -> Bronze | O1: =IFERROR(__xludf.DUMMYFUNCTION("""COMPUTED_VALUE"""),"Silver") -> Silver | P1: =IFERROR(__xludf.DUMMYFUNCTION("""COMPUTED_VALUE"""),"Gold") -> Gold
C2: Scenario | F2: High Score | G2: Progress | H2: =iferror(trunc(harmean(H3:H20)), 0) -> 0 | M2: =IFERROR(__xludf.DUMMYFUNCTION("""COMPUTED_VALUE"""),100.0) -> 100 | N2: =IFERROR(__xludf.DUMMYFUNCTION("""COMPUTED_VALUE"""),200.0) -> 200 | O2: =IFERROR(__xludf.DUMMYFUNCTION("""COMPUTED_VALUE"""),300.0) -> 300 | P2: =IFERROR(__xludf.DUMMYFUNCTION("""COMPUTED_VALUE"""),400.0) -> 400
A3: Clicking | B3: Dynamic | C3: =IFERROR(__xludf.DUMMYFUNCTION("importrange(""https://docs.google.com/spreadsheets/d/1JxRnDKurkxZO94D2V46kmGWozPF7dbOpsMfWZL85LvU"", ""Novice!C3:C20"")")," VT Pasu Novice S5") -> VT Pasu Novice S5 | G3: =IFERROR(__xludf.DUMMYFUNCTION("sparkline( F3 - choose(match(F3, {0, M3:P3}), 0, M3, N3, O3, P3), { ""charttype"", ""bar""; ""max"", choose(match(F3, {0, M3:P3}), M3, N3-M3, O3-N3, P3-O3, 0); ""nan"", ""ignore""; ""color1"", iferror(choose(match(F3, {0, M3:P3}), "&" ""#999999"", ""#ff9900"", ""#cbd9e6"", ""#cab148"", ""#e5d9b4"" )) } ) "),"") | H3: {=trunc(min(Intermediate!M$2, max( choose(match(F3, {0, M3:P3}), 0, M$2, N$2, O$2, P$2) + (F3 - choose(match(F3, {0, M3:P3}), 0, M3, N3, O3, P3)) / choose(match(F3, {0, M3:P3}), M3, N3-M3, O3-N3, P3-O3, P3-O3) * choose(match(F3, {0, M3:P3}), M$2, N$2-M$2, O$2-N$2, P$2-O$2, P$2-O$2), choose(match(F4, {0, M4:P4}), 0, M$2, N$2, O$2, P$2) + (F4 - choose(match(F4, {0, M4:P4}), 0, M4, N4, O4, P4)) / choose(match(F4, {0, M4:P4}), M4, N4-M4, O4-N4, P4-O4, P4-O4) * choose(match(F4, {0, M4:P4}), M$2, N$2-M$2, O$2-N$2, P$2-O$2, P$2-O$2) )))} -> 0 | M3: =IFERROR(__xludf.DUMMYFUNCTION("""COMPUTED_VALUE"""),555.0) -> 555 | N3: =IFERROR(__xludf.DUMMYFUNCTION("""COMPUTED_VALUE"""),660.0) -> 660 | O3: =IFERROR(__xludf.DUMMYFUNCTION("""COMPUTED_VALUE"""),745.0) -> 745 | P3: =IFERROR(__xludf.DUMMYFUNCTION("""COMPUTED_VALUE"""),800.0) -> 800
C4: =IFERROR(__xludf.DUMMYFUNCTION("""COMPUTED_VALUE""")," VT Popcorn Novice S5") -> VT Popcorn Novice S5 | G4: =IFERROR(__xludf.DUMMYFUNCTION("sparkline( F4 - choose(match(F4, {0, M4:P4}), 0, M4, N4, O4, P4), { ""charttype"", ""bar""; ""max"", choose(match(F4, {0, M4:P4}), M4, N4-M4, O4-N4, P4-O4, 0); ""nan"", ""ignore""; ""color1"", iferror(choose(match(F4, {0, M4:P4}), "&" ""#999999"", ""#ff9900"", ""#cbd9e6"", ""#cab148"", ""#e5d9b4"" )) } ) "),"") | M4: =IFERROR(__xludf.DUMMYFUNCTION("""COMPUTED_VALUE"""),390.0) -> 390 | N4: =IFERROR(__xludf.DUMMYFUNCTION("""COMPUTED_VALUE"""),500.0) -> 500 | O4: =IFERROR(__xludf.DUMMYFUNCTION("""COMPUTED_VALUE"""),600.0) -> 600 | P4: =IFERROR(__xludf.DUMMYFUNCTION("""COMPUTED_VALUE"""),720.0) -> 720
B5: Static | C5: =IFERROR(__xludf.DUMMYFUNCTION("""COMPUTED_VALUE""")," VT 1w4ts Novice S5") -> VT 1w4ts Novice S5 | G5: =IFERROR(__xludf.DUMMYFUNCTION("sparkline( F5 - choose(match(F5, {0, M5:P5}), 0, M5, N5, O5, P5), { ""charttype"", ""bar""; ""max"", choose(match(F5, {0, M5:P5}), M5, N5-M5, O5-N5, P5-O5, 0); ""nan"", ""ignore""; ""color1"", iferror(choose(match(F5, {0, M5:P5}), "&" ""#999999"", ""#ff9900"", ""#cbd9e6"", ""#cab148"", ""#e5d9b4"" )) } ) "),"") | H5: {=trunc(min(Intermediate!M$2, max( choose(match(F5, {0, M5:P5}), 0, M$2, N$2, O$2, P$2) + (F5 - choose(match(F5, {0, M5:P5}), 0, M5, N5, O5, P5)) / choose(match(F5, {0, M5:P5}), M5, N5-M5, O5-N5, P5-O5, P5-O5) * choose(match(F5, {0, M5:P5}), M$2, N$2-M$2, O$2-N$2, P$2-O$2, P$2-O$2), choose(match(F6, {0, M6:P6}), 0, M$2, N$2, O$2, P$2) + (F6 - choose(match(F6, {0, M6:P6}), 0, M6, N6, O6, P6)) / choose(match(F6, {0, M6:P6}), M6, N6-M6, O6-N6, P6-O6, P6-O6) * choose(match(F6, {0, M6:P6}), M$2, N$2-M$2, O$2-N$2, P$2-O$2, P$2-O$2) )))} -> 0 | M5: =IFERROR(__xludf.DUMMYFUNCTION("""COMPUTED_VALUE"""),820.0) -> 820 | N5: =IFERROR(__xludf.DUMMYFUNCTION("""COMPUTED_VALUE"""),915.0) -> 915 | O5: =IFERROR(__xludf.DUMMYFUNCTION("""COMPUTED_VALUE"""),1010.0) -> 1010 | P5: =IFERROR(__xludf.DUMMYFUNCTION("""COMPUTED_VALUE"""),1110.0) -> 1110
C6: =IFERROR(__xludf.DUMMYFUNCTION("""COMPUTED_VALUE""")," VT ww5t Novice S5") -> VT ww5t Novice S5 | G6: =IFERROR(__xludf.DUMMYFUNCTION("sparkline( F6 - choose(match(F6, {0, M6:P6}), 0, M6, N6, O6, P6), { ""charttype"", ""bar""; ""max"", choose(match(F6, {0, M6:P6}), M6, N6-M6, O6-N6, P6-O6, 0); ""nan"", ""ignore""; ""color1"", iferror(choose(match(F6, {0, M6:P6}), "&" ""#999999"", ""#ff9900"", ""#cbd9e6"", ""#cab148"", ""#e5d9b4"" )) } ) "),"") | M6: =IFERROR(__xludf.DUMMYFUNCTION("""COMPUTED_VALUE"""),990.0) -> 990 | N6: =IFERROR(__xludf.DUMMYFUNCTION("""COMPUTED_VALUE"""),1090.0) -> 1090 | O6: =IFERROR(__xludf.DUMMYFUNCTION("""COMPUTED_VALUE"""),1190.0) -> 1190 | P6: =IFERROR(__xludf.DUMMYFUNCTION("""COMPUTED_VALUE"""),1290.0) -> 1290
B7: Linear | C7: =IFERROR(__xludf.DUMMYFUNCTION("""COMPUTED_VALUE""")," VT Frogtagon Novice S5") -> VT Frogtagon Novice S5 | G7: =IFERROR(__xludf.DUMMYFUNCTION("sparkline( F7 - choose(match(F7, {0, M7:P7}), 0, M7, N7, O7, P7), { ""charttype"", ""bar""; ""max"", choose(match(F7, {0, M7:P7}), M7, N7-M7, O7-N7, P7-O7, 0); ""nan"", ""ignore""; ""color1"", iferror(choose(match(F7, {0, M7:P7}), "&" ""#999999"", ""#ff9900"", ""#cbd9e6"", ""#cab148"", ""#e5d9b4"" )) } ) "),"") | H7: {=trunc(min(Intermediate!M$2, max( choose(match(F7, {0, M7:P7}), 0, M$2, N$2, O$2, P$2) + (F7 - choose(match(F7, {0, M7:P7}), 0, M7, N7, O7, P7)) / choose(match(F7, {0, M7:P7}), M7, N7-M7, O7-N7, P7-O7, P7-O7) * choose(match(F7, {0, M7:P7}), M$2, N$2-M$2, O$2-N$2, P$2-O$2, P$2-O$2), choose(match(F8, {0, M8:P8}), 0, M$2, N$2, O$2, P$2) + (F8 - choose(match(F8, {0, M8:P8}), 0, M8, N8, O8, P8)) / choose(match(F8, {0, M8:P8}), M8, N8-M8, O8-N8, P8-O8, P8-O8) * choose(match(F8, {0, M8:P8}), M$2, N$2-M$2, O$2-N$2, P$2-O$2, P$2-O$2) )))} -> 0 | M7: =IFERROR(__xludf.DUMMYFUNCTION("""COMPUTED_VALUE"""),620.0) -> 620 | N7: =IFERROR(__xludf.DUMMYFUNCTION("""COMPUTED_VALUE"""),740.0) -> 740 | O7: =IFERROR(__xludf.DUMMYFUNCTION("""COMPUTED_VALUE"""),850.0) -> 850 | P7: =IFERROR(__xludf.DUMMYFUNCTION("""COMPUTED_VALUE"""),980.0) -> 980
C8: =IFERROR(__xludf.DUMMYFUNCTION("""COMPUTED_VALUE""")," VT Floating Heads Novice S5") -> VT Floating Heads Novice S5 | G8: =IFERROR(__xludf.DUMMYFUNCTION("sparkline( F8 - choose(match(F8, {0, M8:P8}), 0, M8, N8, O8, P8), { ""charttype"", ""bar""; ""max"", choose(match(F8, {0, M8:P8}), M8, N8-M8, O8-N8, P8-O8, 0); ""nan"", ""ignore""; ""color1"", iferror(choose(match(F8, {0, M8:P8}), "&" ""#999999"", ""#ff9900"", ""#cbd9e6"", ""#cab148"", ""#e5d9b4"" )) } ) "),"") | M8: =IFERROR(__xludf.DUMMYFUNCTION("""COMPUTED_VALUE"""),375.0) -> 375 | N8: =IFERROR(__xludf.DUMMYFUNCTION("""COMPUTED_VALUE"""),460.0) -> 460 | O8: =IFERROR(__xludf.DUMMYFUNCTION("""COMPUTED_VALUE"""),540.0) -> 540 | P8: =IFERROR(__xludf.DUMMYFUNCTION("""COMPUTED_VALUE"""),640.0) -> 640
A9: Tracking | B9: Precise | C9: =IFERROR(__xludf.DUMMYFUNCTION("""COMPUTED_VALUE""")," VT PGT Novice S5") -> VT PGT Novice S5 | G9: =IFERROR(__xludf.DUMMYFUNCTION("sparkline( F9 - choose(match(F9, {0, M9:P9}), 0, M9, N9, O9, P9), { ""charttype"", ""bar""; ""max"", choose(match(F9, {0, M9:P9}), M9, N9-M9, O9-N9, P9-O9, 0); ""nan"", ""ignore""; ""color1"", iferror(choose(match(F9, {0, M9:P9}), "&" ""#999999"", ""#ff9900"", ""#cbd9e6"", ""#cab148"", ""#e5d9b4"" )) } ) "),"") | H9: {=trunc(min(Intermediate!M$2, max( choose(match(F9, {0, M9:P9}), 0, M$2, N$2, O$2, P$2) + (F9 - choose(match(F9, {0, M9:P9}), 0, M9, N9, O9, P9)) / choose(match(F9, {0, M9:P9}), M9, N9-M9, O9-N9, P9-O9, P9-O9) * choose(match(F9, {0, M9:P9}), M$2, N$2-M$2, O$2-N$2, P$2-O$2, P$2-O$2), choose(match(F10, {0, M10:P10}), 0, M$2, N$2, O$2, P$2) + (F10 - choose(match(F10, {0, M10:P10}), 0, M10, N10, O10, P10)) / choose(match(F10, {0, M10:P10}), M10, N10-M10, O10-N10, P10-O10, P10-O10) * choose(match(F10, {0, M10:P10}), M$2, N$2-M$2, O$2-N$2, P$2-O$2, P$2-O$2) )))} -> 0 | M9: =IFERROR(__xludf.DUMMYFUNCTION("""COMPUTED_VALUE"""),1900.0) -> 1900 | N9: =IFERROR(__xludf.DUMMYFUNCTION("""COMPUTED_VALUE"""),2325.0) -> 2325 | O9: =IFERROR(__xludf.DUMMYFUNCTION("""COMPUTED_VALUE"""),2775.0) -> 2775 | P9: =IFERROR(__xludf.DUMMYFUNCTION("""COMPUTED_VALUE"""),3050.0) -> 3050
C10: =IFERROR(__xludf.DUMMYFUNCTION("""COMPUTED_VALUE""")," VT Snake Track Novice S5") -> VT Snake Track Novice S5 | G10: =IFERROR(__xludf.DUMMYFUNCTION("sparkline( F10 - choose(match(F10, {0, M10:P10}), 0, M10, N10, O10, P10), { ""charttype"", ""bar""; ""max"", choose(match(F10, {0, M10:P10}), M10, N10-M10, O10-N10, P10-O10, 0); ""nan"", ""ignore""; ""color1"", iferror(choose(match(F10"&", {0, M10:P10}), ""#999999"", ""#ff9900"", ""#cbd9e6"", ""#cab148"", ""#e5d9b4"" )) } ) "),"") | M10: =IFERROR(__xludf.DUMMYFUNCTION("""COMPUTED_VALUE"""),2400.0) -> 2400 | N10: =IFERROR(__xludf.DUMMYFUNCTION("""COMPUTED_VALUE"""),2750.0) -> 2750 | O10: =IFERROR(__xludf.DUMMYFUNCTION("""COMPUTED_VALUE"""),3125.0) -> 3125 | P10: =IFERROR(__xludf.DUMMYFUNCTION("""COMPUTED_VALUE"""),3425.0) -> 3425
B11: Reactive | C11: =IFERROR(__xludf.DUMMYFUNCTION("""COMPUTED_VALUE""")," VT Aether Novice S5") -> VT Aether Novice S5 | G11: =IFERROR(__xludf.DUMMYFUNCTION("sparkline( F11 - choose(match(F11, {0, M11:P11}), 0, M11, N11, O11, P11), { ""charttype"", ""bar""; ""max"", choose(match(F11, {0, M11:P11}), M11, N11-M11, O11-N11, P11-O11, 0); ""nan"", ""ignore""; ""color1"", iferror(choose(match(F11"&", {0, M11:P11}), ""#999999"", ""#ff9900"", ""#cbd9e6"", ""#cab148"", ""#e5d9b4"" )) } ) "),"") | H11: {=trunc(min(Intermediate!M$2, max( choose(match(F11, {0, M11:P11}), 0, M$2, N$2, O$2, P$2) + (F11 - choose(match(F11, {0, M11:P11}), 0, M11, N11, O11, P11)) / choose(match(F11, {0, M11:P11}), M11, N11-M11, O11-N11, P11-O11, P11-O11) * choose(match(F11, {0, M11:P11}), M$2, N$2-M$2, O$2-N$2, P$2-O$2, P$2-O$2), choose(match(F12, {0, M12:P12}), 0, M$2, N$2, O$2, P$2) + (F12 - choose(match(F12, {0, M12:P12}), 0, M12, N12, O12, P12)) / choose(match(F12, {0, M12:P12}), M12, N12-M12, O12-N12, P12-O12, P12-O12) * choose(match(F12, {0, M12:P12}), M$2, N$2-M$2, O$2-N$2, P$2-O$2, P$2-O$2) )))} -> 0 | M11: =IFERROR(__xludf.DUMMYFUNCTION("""COMPUTED_VALUE"""),1525.0) -> 1525 | N11: =IFERROR(__xludf.DUMMYFUNCTION("""COMPUTED_VALUE"""),1900.0) -> 1900 | O11: =IFERROR(__xludf.DUMMYFUNCTION("""COMPUTED_VALUE"""),2250.0) -> 2250 | P11: =IFERROR(__xludf.DUMMYFUNCTION("""COMPUTED_VALUE"""),2650.0) -> 2650
C12: =IFERROR(__xludf.DUMMYFUNCTION("""COMPUTED_VALUE""")," VT Ground Novice S5") -> VT Ground Novice S5 | G12: =IFERROR(__xludf.DUMMYFUNCTION("sparkline( F12 - choose(match(F12, {0, M12:P12}), 0, M12, N12, O12, P12), { ""charttype"", ""bar""; ""max"", choose(match(F12, {0, M12:P12}), M12, N12-M12, O12-N12, P12-O12, 0); ""nan"", ""ignore""; ""color1"", iferror(choose(match(F12"&", {0, M12:P12}), ""#999999"", ""#ff9900"", ""#cbd9e6"", ""#cab148"", ""#e5d9b4"" )) } ) "),"") | M12: =IFERROR(__xludf.DUMMYFUNCTION("""COMPUTED_VALUE"""),2100.0) -> 2100 | N12: =IFERROR(__xludf.DUMMYFUNCTION("""COMPUTED_VALUE"""),2500.0) -> 2500 | O12: =IFERROR(__xludf.DUMMYFUNCTION("""COMPUTED_VALUE"""),2825.0) -> 2825 | P12: =IFERROR(__xludf.DUMMYFUNCTION("""COMPUTED_VALUE"""),3100.0) -> 3100
B13: Control | C13: =IFERROR(__xludf.DUMMYFUNCTION("""COMPUTED_VALUE""")," VT Raw Control Novice S5") -> VT Raw Control Novice S5 | G13: =IFERROR(__xludf.DUMMYFUNCTION("sparkline( F13 - choose(match(F13, {0, M13:P13}), 0, M13, N13, O13, P13), { ""charttype"", ""bar""; ""max"", choose(match(F13, {0, M13:P13}), M13, N13-M13, O13-N13, P13-O13, 0); ""nan"", ""ignore""; ""color1"", iferror(choose(match(F13"&", {0, M13:P13}), ""#999999"", ""#ff9900"", ""#cbd9e6"", ""#cab148"", ""#e5d9b4"" )) } ) "),"") | H13: {=trunc(min(Intermediate!M$2, max( choose(match(F13, {0, M13:P13}), 0, M$2, N$2, O$2, P$2) + (F13 - choose(match(F13, {0, M13:P13}), 0, M13, N13, O13, P13)) / choose(match(F13, {0, M13:P13}), M13, N13-M13, O13-N13, P13-O13, P13-O13) * choose(match(F13, {0, M13:P13}), M$2, N$2-M$2, O$2-N$2, P$2-O$2, P$2-O$2), choose(match(F14, {0, M14:P14}), 0, M$2, N$2, O$2, P$2) + (F14 - choose(match(F14, {0, M14:P14}), 0, M14, N14, O14, P14)) / choose(match(F14, {0, M14:P14}), M14, N14-M14, O14-N14, P14-O14, P14-O14) * choose(match(F14, {0, M14:P14}), M$2, N$2-M$2, O$2-N$2, P$2-O$2, P$2-O$2) )))} -> 0 | M13: =IFERROR(__xludf.DUMMYFUNCTION("""COMPUTED_VALUE"""),2125.0) -> 2125 | N13: =IFERROR(__xludf.DUMMYFUNCTION("""COMPUTED_VALUE"""),2550.0) -> 2550 | O13: =IFERROR(__xludf.DUMMYFUNCTION("""COMPUTED_VALUE"""),2975.0) -> 2975 | P13: =IFERROR(__xludf.DUMMYFUNCTION("""COMPUTED_VALUE"""),3450.0) -> 3450
C14: =IFERROR(__xludf.DUMMYFUNCTION("""COMPUTED_VALUE""")," VT Controlsphere Novice S5") -> VT Controlsphere Novice S5 | G14: =IFERROR(__xludf.DUMMYFUNCTION("sparkline( F14 - choose(match(F14, {0, M14:P14}), 0, M14, N14, O14, P14), { ""charttype"", ""bar""; ""max"", choose(match(F14, {0, M14:P14}), M14, N14-M14, O14-N14, P14-O14, 0); ""nan"", ""ignore""; ""color1"", iferror(choose(match(F14"&", {0, M14:P14}), ""#999999"", ""#ff9900"", ""#cbd9e6"", ""#cab148"", ""#e5d9b4"" )) } ) "),"") | M14: =IFERROR(__xludf.DUMMYFUNCTION("""COMPUTED_VALUE"""),1575.0) -> 1575 | N14: =IFERROR(__xludf.DUMMYFUNCTION("""COMPUTED_VALUE"""),1950.0) -> 1950 | O14: =IFERROR(__xludf.DUMMYFUNCTION("""COMPUTED_VALUE"""),2400.0) -> 2400 | P14: =IFERROR(__xludf.DUMMYFUNCTION("""COMPUTED_VALUE"""),2900.0) -> 2900
A15: Switching | B15: Speed | C15: =IFERROR(__xludf.DUMMYFUNCTION("""COMPUTED_VALUE""")," VT DotTS Novice S5") -> VT DotTS Novice S5 | G15: =IFERROR(__xludf.DUMMYFUNCTION("sparkline( F15 - choose(match(F15, {0, M15:P15}), 0, M15, N15, O15, P15), { ""charttype"", ""bar""; ""max"", choose(match(F15, {0, M15:P15}), M15, N15-M15, O15-N15, P15-O15, 0); ""nan"", ""ignore""; ""color1"", iferror(choose(match(F15"&", {0, M15:P15}), ""#999999"", ""#ff9900"", ""#cbd9e6"", ""#cab148"", ""#e5d9b4"" )) } ) "),"") | H15: {=trunc(min(Intermediate!M$2, max( choose(match(F15, {0, M15:P15}), 0, M$2, N$2, O$2, P$2) + (F15 - choose(match(F15, {0, M15:P15}), 0, M15, N15, O15, P15)) / choose(match(F15, {0, M15:P15}), M15, N15-M15, O15-N15, P15-O15, P15-O15) * choose(match(F15, {0, M15:P15}), M$2, N$2-M$2, O$2-N$2, P$2-O$2, P$2-O$2), choose(match(F16, {0, M16:P16}), 0, M$2, N$2, O$2, P$2) + (F16 - choose(match(F16, {0, M16:P16}), 0, M16, N16, O16, P16)) / choose(match(F16, {0, M16:P16}), M16, N16-M16, O16-N16, P16-O16, P16-O16) * choose(match(F16, {0, M16:P16}), M$2, N$2-M$2, O$2-N$2, P$2-O$2, P$2-O$2) )))} -> 0 | M15: =IFERROR(__xludf.DUMMYFUNCTION("""COMPUTED_VALUE"""),845.0) -> 845 | N15: =IFERROR(__xludf.DUMMYFUNCTION("""COMPUTED_VALUE"""),940.0) -> 940 | O15: =IFERROR(__xludf.DUMMYFUNCTION("""COMPUTED_VALUE"""),1030.0) -> 1030 | P15: =IFERROR(__xludf.DUMMYFUNCTION("""COMPUTED_VALUE"""),1090.0) -> 1090
C16: =IFERROR(__xludf.DUMMYFUNCTION("""COMPUTED_VALUE""")," VT EddieTS Novice S5") -> VT EddieTS Novice S5 | G16: =IFERROR(__xludf.DUMMYFUNCTION("sparkline( F16 - choose(match(F16, {0, M16:P16}), 0, M16, N16, O16, P16), { ""charttype"", ""bar""; ""max"", choose(match(F16, {0, M16:P16}), M16, N16-M16, O16-N16, P16-O16, 0); ""nan"", ""ignore""; ""color1"", iferror(choose(match(F16"&", {0, M16:P16}), ""#999999"", ""#ff9900"", ""#cbd9e6"", ""#cab148"", ""#e5d9b4"" )) } ) "),"") | M16: =IFERROR(__xludf.DUMMYFUNCTION("""COMPUTED_VALUE"""),640.0) -> 640 | N16: =IFERROR(__xludf.DUMMYFUNCTION("""COMPUTED_VALUE"""),730.0) -> 730 | O16: =IFERROR(__xludf.DUMMYFUNCTION("""COMPUTED_VALUE"""),810.0) -> 810 | P16: =IFERROR(__xludf.DUMMYFUNCTION("""COMPUTED_VALUE"""),890.0) -> 890
B17: Evasive | C17: =IFERROR(__xludf.DUMMYFUNCTION("""COMPUTED_VALUE""")," VT DriftTS Novice S5") -> VT DriftTS Novice S5 | G17: =IFERROR(__xludf.DUMMYFUNCTION("sparkline( F17 - choose(match(F17, {0, M17:P17}), 0, M17, N17, O17, P17), { ""charttype"", ""bar""; ""max"", choose(match(F17, {0, M17:P17}), M17, N17-M17, O17-N17, P17-O17, 0); ""nan"", ""ignore""; ""color1"", iferror(choose(match(F17"&", {0, M17:P17}), ""#999999"", ""#ff9900"", ""#cbd9e6"", ""#cab148"", ""#e5d9b4"" )) } ) "),"") | H17: {=trunc(min(Intermediate!M$2, max( choose(match(F17, {0, M17:P17}), 0, M$2, N$2, O$2, P$2) + (F17 - choose(match(F17, {0, M17:P17}), 0, M17, N17, O17, P17)) / choose(match(F17, {0, M17:P17}), M17, N17-M17, O17-N17, P17-O17, P17-O17) * choose(match(F17, {0, M17:P17}), M$2, N$2-M$2, O$2-N$2, P$2-O$2, P$2-O$2), choose(match(F18, {0, M18:P18}), 0, M$2, N$2, O$2, P$2) + (F18 - choose(match(F18, {0, M18:P18}), 0, M18, N18, O18, P18)) / choose(match(F18, {0, M18:P18}), M18, N18-M18, O18-N18, P18-O18, P18-O18) * choose(match(F18, {0, M18:P18}), M$2, N$2-M$2, O$2-N$2, P$2-O$2, P$2-O$2) )))} -> 0 | M17: =IFERROR(__xludf.DUMMYFUNCTION("""COMPUTED_VALUE"""),315.0) -> 315 | N17: =IFERROR(__xludf.DUMMYFUNCTION("""COMPUTED_VALUE"""),355.0) -> 355 | O17: =IFERROR(__xludf.DUMMYFUNCTION("""COMPUTED_VALUE"""),390.0) -> 390 | P17: =IFERROR(__xludf.DUMMYFUNCTION("""COMPUTED_VALUE"""),430.0) -> 430
C18: =IFERROR(__xludf.DUMMYFUNCTION("""COMPUTED_VALUE""")," VT FlyTS Novice S5") -> VT FlyTS Novice S5 | G18: =IFERROR(__xludf.DUMMYFUNCTION("sparkline( F18 - choose(match(F18, {0, M18:P18}), 0, M18, N18, O18, P18), { ""charttype"", ""bar""; ""max"", choose(match(F18, {0, M18:P18}), M18, N18-M18, O18-N18, P18-O18, 0); ""nan"", ""ignore""; ""color1"", iferror(choose(match(F18"&", {0, M18:P18}), ""#999999"", ""#ff9900"", ""#cbd9e6"", ""#cab148"", ""#e5d9b4"" )) } ) "),"") | M18: =IFERROR(__xludf.DUMMYFUNCTION("""COMPUTED_VALUE"""),420.0) -> 420 | N18: =IFERROR(__xludf.DUMMYFUNCTION("""COMPUTED_VALUE"""),460.0) -> 460 | O18: =IFERROR(__xludf.DUMMYFUNCTION("""COMPUTED_VALUE"""),500.0) -> 500 | P18: =IFERROR(__xludf.DUMMYFUNCTION("""COMPUTED_VALUE"""),535.0) -> 535
B19: Stability | C19: =IFERROR(__xludf.DUMMYFUNCTION("""COMPUTED_VALUE""")," VT ControlTS Novice S5") -> VT ControlTS Novice S5 | G19: =IFERROR(__xludf.DUMMYFUNCTION("sparkline( F19 - choose(match(F19, {0, M19:P19}), 0, M19, N19, O19, P19), { ""charttype"", ""bar""; ""max"", choose(match(F19, {0, M19:P19}), M19, N19-M19, O19-N19, P19-O19, 0); ""nan"", ""ignore""; ""color1"", iferror(choose(match(F19"&", {0, M19:P19}), ""#999999"", ""#ff9900"", ""#cbd9e6"", ""#cab148"", ""#e5d9b4"" )) } ) "),"") | H19: {=trunc(min(Intermediate!M$2, max( choose(match(F19, {0, M19:P19}), 0, M$2, N$2, O$2, P$2) + (F19 - choose(match(F19, {0, M19:P19}), 0, M19, N19, O19, P19)) / choose(match(F19, {0, M19:P19}), M19, N19-M19, O19-N19, P19-O19, P19-O19) * choose(match(F19, {0, M19:P19}), M$2, N$2-M$2, O$2-N$2, P$2-O$2, P$2-O$2), choose(match(F20, {0, M20:P20}), 0, M$2, N$2, O$2, P$2) + (F20 - choose(match(F20, {0, M20:P20}), 0, M20, N20, O20, P20)) / choose(match(F20, {0, M20:P20}), M20, N20-M20, O20-N20, P20-O20, P20-O20) * choose(match(F20, {0, M20:P20}), M$2, N$2-M$2, O$2-N$2, P$2-O$2, P$2-O$2) )))} -> 0 | M19: =IFERROR(__xludf.DUMMYFUNCTION("""COMPUTED_VALUE"""),340.0) -> 340 | N19: =IFERROR(__xludf.DUMMYFUNCTION("""COMPUTED_VALUE"""),380.0) -> 380 | O19: =IFERROR(__xludf.DUMMYFUNCTION("""COMPUTED_VALUE"""),420.0) -> 420 | P19: =IFERROR(__xludf.DUMMYFUNCTION("""COMPUTED_VALUE"""),450.0) -> 450
C20: =IFERROR(__xludf.DUMMYFUNCTION("""COMPUTED_VALUE""")," VT Penta Bounce Novice S5") -> VT Penta Bounce Novice S5 | G20: =IFERROR(__xludf.DUMMYFUNCTION("sparkline( F20 - choose(match(F20, {0, M20:P20}), 0, M20, N20, O20, P20), { ""charttype"", ""bar""; ""max"", choose(match(F20, {0, M20:P20}), M20, N20-M20, O20-N20, P20-O20, 0); ""nan"", ""ignore""; ""color1"", iferror(choose(match(F20"&", {0, M20:P20}), ""#999999"", ""#ff9900"", ""#cbd9e6"", ""#cab148"", ""#e5d9b4"" )) } ) "),"") | M20: =IFERROR(__xludf.DUMMYFUNCTION("""COMPUTED_VALUE"""),290.0) -> 290 | N20: =IFERROR(__xludf.DUMMYFUNCTION("""COMPUTED_VALUE"""),340.0) -> 340 | O20: =IFERROR(__xludf.DUMMYFUNCTION("""COMPUTED_VALUE"""),390.0) -> 390 | P20: =IFERROR(__xludf.DUMMYFUNCTION("""COMPUTED_VALUE"""),445.0) -> 445
A21: Sharecode | G21: =IFERROR(__xludf.DUMMYFUNCTION("if(importrange(""https://docs.google.com/spreadsheets/d/1JxRnDKurkxZO94D2V46kmGWozPF7dbOpsMfWZL85LvU"", ""Changelog!A2:A2"")=indirect(""Changelog!A2""), concatenate(""Sheet Version: "", Changelog!A2), hyperlink(""https://docs.google.com/spreadsheets/d/1Jx"&"RnDKurkxZO94D2V46kmGWozPF7dbOpsMfWZL85LvU"", ""Outdated version, click link & make a new copy!""))"),"Sheet Version: 1.0.7") -> Sheet Version: 1.0.7 | N21: =HYPERLINK("https://voltaic.gg/", "Website↗") -> Website↗ | O21: =HYPERLINK("http://discord.gg/voltaic","Discord↗") -> Discord↗ | P21: =HYPERLINK("http://twitter.com/voltaichq","Twitter↗") -> Twitter↗
A22: KovaaKsBouncingSilverBinding
A23: Find more resources in discord.gg/voltaic | N23: =HYPERLINK("https://www.youtube.com/voltaichq","YouTube↗") -> YouTube↗ | O23: =HYPERLINK("https://bit.ly/VTxKvKsGuide","Guide↗") -> Guide↗ | P23: =HYPERLINK("https://docs.google.com/document/d/1omExq_y4ld9vkvbTFkLdjlT5UwQpvYSgyk5PgA7nrzM/edit?usp=sharing","Rules↗") -> Rules↗

Sheet Intermediate
A1: Voltaic KvKs Intermediate Benchmarks S5 BETA | E1: {=concatenate(choose(match(H2, {0, M2:P2}), "Unranked", M1, N1, O1, P1), if(and(F3:F20 >= choose(match(H2, {0, M2:P2}), 1E+99, M3:M20, N3:N20, O3:O20, P3:P20)), " Complete", ""))} -> Platinum | H1: Energy | M1: =IFERROR(__xludf.DUMMYFUNCTION("importrange(""https://docs.google.com/spreadsheets/d/1JxRnDKurkxZO94D2V46kmGWozPF7dbOpsMfWZL85LvU"", ""Intermediate!M1:P20"")"),"Platinum") -> Platinum | N1: =IFERROR(__xludf.DUMMYFUNCTION("""COMPUTED_VALUE"""),"Diamond") -> Diamond | O1: =IFERROR(__xludf.DUMMYFUNCTION("""COMPUTED_VALUE"""),"Jade") -> Jade | P1: =IFERROR(__xludf.DUMMYFUNCTION("""COMPUTED_VALUE"""),"Master") -> Master
C2: Scenario | F2: High Score | G2: Progress | H2: =iferror(trunc(harmean(H3:H20)), 0) -> 533 | M2: =IFERROR(__xludf.DUMMYFUNCTION("""COMPUTED_VALUE"""),500.0) -> 500 | N2: =IFERROR(__xludf.DUMMYFUNCTION("""COMPUTED_VALUE"""),600.0) -> 600 | O2: =IFERROR(__xludf.DUMMYFUNCTION("""COMPUTED_VALUE"""),700.0) -> 700 | P2: =IFERROR(__xludf.DUMMYFUNCTION("""COMPUTED_VALUE"""),800.0) -> 800
A3: Clicking | B3: Dynamic | C3: =IFERROR(__xludf.DUMMYFUNCTION("importrange(""https://docs.google.com/spreadsheets/d/1JxRnDKurkxZO94D2V46kmGWozPF7dbOpsMfWZL85LvU"", ""Intermediate!C3:C20"")")," VT Pasu Intermediate S5") -> VT Pasu Intermediate S5 | F3: 724 | G3: =IFERROR(__xludf.DUMMYFUNCTION("sparkline( F3 - choose(match(F3, {0, M3:P3}), 0, M3, N3, O3, P3), { ""charttype"", ""bar""; ""max"", choose(match(F3, {0, M3:P3}), M3, N3-M3, O3-N3, P3-O3, 0); ""nan"", ""ignore""; ""color1"", iferror(choose(match(F3, {0, M3:P3}), "&" ""#2FCFC2"", ""#B9F2FF"", ""#85FA85"", ""#EC44CA"", ""#fbc2ea"" )) } ) "),"") | H3: {=trunc(min(Advanced!M$2, max( choose(match(F3, {0, M3-(N3-M3), M3:P3}), 0, Novice!P$2, M$2, N$2, O$2, P$2) + (F3 - choose(match(F3, {0, M3-(N3-M3), M3:P3}), 0, M3-(N3-M3), M3, N3, O3, P3)) / choose(match(F3, {0, M3-(N3-M3), M3:P3}), M3-(N3-M3), N3-M3, N3-M3, O3-N3, P3-O3, P3-O3) * choose(match(F3, {0, M3-(N3-M3), M3:P3}), Novice!P$2, M$2-Novice!P$2, N$2-M$2, O$2-N$2, P$2-O$2, P$2-O$2), choose(match(F4, {0, M4-(N4-M4), M4:P4}), 0, Novice!P$2, M$2, N$2, O$2, P$2) + (F4 - choose(match(F4, {0, M4-(N4-M4), M4:P4}), 0, M4-(N4-M4), M4, N4, O4, P4)) / choose(match(F4, {0, M4-(N4-M4), M4:P4}), M4-(N4-M4), N4-M4, N4-M4, O4-N4, P4-O4, P4-O4) * choose(match(F4, {0, M4-(N4-M4), M4:P4}), Novice!P$2, M$2-Novice!P$2, N$2-M$2, O$2-N$2, P$2-O$2, P$2-O$2) )))} -> 544 | M3: =IFERROR(__xludf.DUMMYFUNCTION("""COMPUTED_VALUE"""),770.0) -> 770 | N3: =IFERROR(__xludf.DUMMYFUNCTION("""COMPUTED_VALUE"""),850.0) -> 850 | O3: =IFERROR(__xludf.DUMMYFUNCTION("""COMPUTED_VALUE"""),930.0) -> 930 | P3: =IFERROR(__xludf.DUMMYFUNCTION("""COMPUTED_VALUE"""),980.0) -> 980
C4: =IFERROR(__xludf.DUMMYFUNCTION("""COMPUTED_VALUE""")," VT Popcorn Intermediate S5") -> VT Popcorn Intermediate S5 | F4: 640 | G4: =IFERROR(__xludf.DUMMYFUNCTION("sparkline( F4 - choose(match(F4, {0, M4:P4}), 0, M4, N4, O4, P4), { ""charttype"", ""bar""; ""max"", choose(match(F4, {0, M4:P4}), M4, N4-M4, O4-N4, P4-O4, 0); ""nan"", ""ignore""; ""color1"", iferror(choose(match(F4, {0, M4:P4}), "&" ""#2FCFC2"", ""#B9F2FF"", ""#85FA85"", ""#EC44CA"", ""#fbc2ea"" )) } ) "),"") | M4: =IFERROR(__xludf.DUMMYFUNCTION("""COMPUTED_VALUE"""),600.0) -> 600 | N4: =IFERROR(__xludf.DUMMYFUNCTION("""COMPUTED_VALUE"""),690.0) -> 690 | O4: =IFERROR(__xludf.DUMMYFUNCTION("""COMPUTED_VALUE"""),780.0) -> 780 | P4: =IFERROR(__xludf.DUMMYFUNCTION("""COMPUTED_VALUE"""),860.0) -> 860
B5: Static | C5: =IFERROR(__xludf.DUMMYFUNCTION("""COMPUTED_VALUE""")," VT 1w3ts Intermediate S5") -> VT 1w3ts Intermediate S5 | F5: 962 | G5: =IFERROR(__xludf.DUMMYFUNCTION("sparkline( F5 - choose(match(F5, {0, M5:P5}), 0, M5, N5, O5, P5), { ""charttype"", ""bar""; ""max"", choose(match(F5, {0, M5:P5}), M5, N5-M5, O5-N5, P5-O5, 0); ""nan"", ""ignore""; ""color1"", iferror(choose(match(F5, {0, M5:P5}), "&" ""#2FCFC2"", ""#B9F2FF"", ""#85FA85"", ""#EC44CA"", ""#fbc2ea"" )) } ) "),"") | H5: {=trunc(min(Advanced!M$2, max( choose(match(F5, {0, M5-(N5-M5), M5:P5}), 0, Novice!P$2, M$2, N$2, O$2, P$2) + (F5 - choose(match(F5, {0, M5-(N5-M5), M5:P5}), 0, M5-(N5-M5), M5, N5, O5, P5)) / choose(match(F5, {0, M5-(N5-M5), M5:P5}), M5-(N5-M5), N5-M5, N5-M5, O5-N5, P5-O5, P5-O5) * choose(match(F5, {0, M5-(N5-M5), M5:P5}), Novice!P$2, M$2-Novice!P$2, N$2-M$2, O$2-N$2, P$2-O$2, P$2-O$2), choose(match(F6, {0, M6-(N6-M6), M6:P6}), 0, Novice!P$2, M$2, N$2, O$2, P$2) + (F6 - choose(match(F6, {0, M6-(N6-M6), M6:P6}), 0, M6-(N6-M6), M6, N6, O6, P6)) / choose(match(F6, {0, M6-(N6-M6), M6:P6}), M6-(N6-M6), N6-M6, N6-M6, O6-N6, P6-O6, P6-O6) * choose(match(F6, {0, M6-(N6-M6), M6:P6}), Novice!P$2, M$2-Novice!P$2, N$2-M$2, O$2-N$2, P$2-O$2, P$2-O$2) )))} -> 377 | M5: =IFERROR(__xludf.DUMMYFUNCTION("""COMPUTED_VALUE"""),1120.0) -> 1120 | N5: =IFERROR(__xludf.DUMMYFUNCTION("""COMPUTED_VALUE"""),1220.0) -> 1220 | O5: =IFERROR(__xludf.DUMMYFUNCTION("""COMPUTED_VALUE"""),1300.0) -> 1300 | P5: =IFERROR(__xludf.DUMMYFUNCTION("""COMPUTED_VALUE"""),1380.0) -> 1380
C6: =IFERROR(__xludf.DUMMYFUNCTION("""COMPUTED_VALUE""")," VT ww5t Intermediate S5") -> VT ww5t Intermediate S5 | F6: 1140 | G6: =IFERROR(__xludf.DUMMYFUNCTION("sparkline( F6 - choose(match(F6, {0, M6:P6}), 0, M6, N6, O6, P6), { ""charttype"", ""bar""; ""max"", choose(match(F6, {0, M6:P6}), M6, N6-M6, O6-N6, P6-O6, 0); ""nan"", ""ignore""; ""color1"", iferror(choose(match(F6, {0, M6:P6}), "&" ""#2FCFC2"", ""#B9F2FF"", ""#85FA85"", ""#EC44CA"", ""#fbc2ea"" )) } ) "),"") | M6: =IFERROR(__xludf.DUMMYFUNCTION("""COMPUTED_VALUE"""),1310.0) -> 1310 | N6: =IFERROR(__xludf.DUMMYFUNCTION("""COMPUTED_VALUE"""),1400.0) -> 1400 | O6: =IFERROR(__xludf.DUMMYFUNCTION("""COMPUTED_VALUE"""),1490.0) -> 1490 | P6: =IFERROR(__xludf.DUMMYFUNCTION("""COMPUTED_VALUE"""),1560.0) -> 1560
B7: Linear | C7: =IFERROR(__xludf.DUMMYFUNCTION("""COMPUTED_VALUE""")," VT Frogtagon Intermediate S5") -> VT Frogtagon Intermediate S5 | F7: 960 | G7: =IFERROR(__xludf.DUMMYFUNCTION("sparkline( F7 - choose(match(F7, {0, M7:P7}), 0, M7, N7, O7, P7), { ""charttype"", ""bar""; ""max"", choose(match(F7, {0, M7:P7}), M7, N7-M7, O7-N7, P7-O7, 0); ""nan"", ""ignore""; ""color1"", iferror(choose(match(F7, {0, M7:P7}), "&" ""#2FCFC2"", ""#B9F2FF"", ""#85FA85"", ""#EC44CA"", ""#fbc2ea"" )) } ) "),"") | H7: {=trunc(min(Advanced!M$2, max( choose(match(F7, {0, M7-(N7-M7), M7:P7}), 0, Novice!P$2, M$2, N$2, O$2, P$2) + (F7 - choose(match(F7, {0, M7-(N7-M7), M7:P7}), 0, M7-(N7-M7), M7, N7, O7, P7)) / choose(match(F7, {0, M7-(N7-M7), M7:P7}), M7-(N7-M7), N7-M7, N7-M7, O7-N7, P7-O7, P7-O7) * choose(match(F7, {0, M7-(N7-M7), M7:P7}), Novice!P$2, M$2-Novice!P$2, N$2-M$2, O$2-N$2, P$2-O$2, P$2-O$2), choose(match(F8, {0, M8-(N8-M8), M8:P8}), 0, Novice!P$2, M$2, N$2, O$2, P$2) + (F8 - choose(match(F8, {0, M8-(N8-M8), M8:P8}), 0, M8-(N8-M8), M8, N8, O8, P8)) / choose(match(F8, {0, M8-(N8-M8), M8:P8}), M8-(N8-M8), N8-M8, N8-M8, O8-N8, P8-O8, P8-O8) * choose(match(F8, {0, M8-(N8-M8), M8:P8}), Novice!P$2, M$2-Novice!P$2, N$2-M$2, O$2-N$2, P$2-O$2, P$2-O$2) )))} -> 520 | M7: =IFERROR(__xludf.DUMMYFUNCTION("""COMPUTED_VALUE"""),940.0) -> 940 | N7: =IFERROR(__xludf.DUMMYFUNCTION("""COMPUTED_VALUE"""),1040.0) -> 1040 | O7: =IFERROR(__xludf.DUMMYFUNCTION("""COMPUTED_VALUE"""),1140.0) -> 1140 | P7: =IFERROR(__xludf.DUMMYFUNCTION("""COMPUTED_VALUE"""),1230.0) -> 1230
C8: =IFERROR(__xludf.DUMMYFUNCTION("""COMPUTED_VALUE""")," VT Floating Heads Intermediate S5") -> VT Floating Heads Intermediate S5 | F8: 615 | G8: =IFERROR(__xludf.DUMMYFUNCTION("sparkline( F8 - choose(match(F8, {0, M8:P8}), 0, M8, N8, O8, P8), { ""charttype"", ""bar""; ""max"", choose(match(F8, {0, M8:P8}), M8, N8-M8, O8-N8, P8-O8, 0); ""nan"", ""ignore""; ""color1"", iferror(choose(match(F8, {0, M8:P8}), "&" ""#2FCFC2"", ""#B9F2FF"", ""#85FA85"", ""#EC44CA"", ""#fbc2ea"" )) } ) "),"") | M8: =IFERROR(__xludf.DUMMYFUNCTION("""COMPUTED_VALUE"""),610.0) -> 610 | N8: =IFERROR(__xludf.DUMMYFUNCTION("""COMPUTED_VALUE"""),690.0) -> 690 | O8: =IFERROR(__xludf.DUMMYFUNCTION("""COMPUTED_VALUE"""),770.0) -> 770 | P8: =IFERROR(__xludf.DUMMYFUNCTION("""COMPUTED_VALUE"""),860.0) -> 860
A9: Tracking | B9: Precise | C9: =IFERROR(__xludf.DUMMYFUNCTION("""COMPUTED_VALUE""")," VT PGT Intermediate S5") -> VT PGT Intermediate S5 | F9: 2538 | G9: =IFERROR(__xludf.DUMMYFUNCTION("sparkline( F9 - choose(match(F9, {0, M9:P9}), 0, M9, N9, O9, P9), { ""charttype"", ""bar""; ""max"", choose(match(F9, {0, M9:P9}), M9, N9-M9, O9-N9, P9-O9, 0); ""nan"", ""ignore""; ""color1"", iferror(choose(match(F9, {0, M9:P9}), "&" ""#2FCFC2"", ""#B9F2FF"", ""#85FA85"", ""#EC44CA"", ""#fbc2ea"" )) } ) "),"") | H9: {=trunc(min(Advanced!M$2, max( choose(match(F9, {0, M9-(N9-M9), M9:P9}), 0, Novice!P$2, M$2, N$2, O$2, P$2) + (F9 - choose(match(F9, {0, M9-(N9-M9), M9:P9}), 0, M9-(N9-M9), M9, N9, O9, P9)) / choose(match(F9, {0, M9-(N9-M9), M9:P9}), M9-(N9-M9), N9-M9, N9-M9, O9-N9, P9-O9, P9-O9) * choose(match(F9, {0, M9-(N9-M9), M9:P9}), Novice!P$2, M$2-Novice!P$2, N$2-M$2, O$2-N$2, P$2-O$2, P$2-O$2), choose(match(F10, {0, M10-(N10-M10), M10:P10}), 0, Novice!P$2, M$2, N$2, O$2, P$2) + (F10 - choose(match(F10, {0, M10-(N10-M10), M10:P10}), 0, M10-(N10-M10), M10, N10, O10, P10)) / choose(match(F10, {0, M10-(N10-M10), M10:P10}), M10-(N10-M10), N10-M10, N10-M10, O10-N10, P10-O10, P10-O10) * choose(match(F10, {0, M10-(N10-M10), M10:P10}), Novice!P$2, M$2-Novice!P$2, N$2-M$2, O$2-N$2, P$2-O$2, P$2-O$2) )))} -> 578 | M9: =IFERROR(__xludf.DUMMYFUNCTION("""COMPUTED_VALUE"""),2275.0) -> 2275 | N9: =IFERROR(__xludf.DUMMYFUNCTION("""COMPUTED_VALUE"""),2675.0) -> 2675 | O9: =IFERROR(__xludf.DUMMYFUNCTION("""COMPUTED_VALUE"""),3050.0) -> 3050 | P9: =IFERROR(__xludf.DUMMYFUNCTION("""COMPUTED_VALUE"""),3325.0) -> 3325
C10: =IFERROR(__xludf.DUMMYFUNCTION("""COMPUTED_VALUE""")," VT Snake Track Intermediate S5") -> VT Snake Track Intermediate S5 | F10: 3096 | G10: =IFERROR(__xludf.DUMMYFUNCTION("sparkline( F10 - choose(match(F10, {0, M10:P10}), 0, M10, N10, O10, P10), { ""charttype"", ""bar""; ""max"", choose(match(F10, {0, M10:P10}), M10, N10-M10, O10-N10, P10-O10, 0); ""nan"", ""ignore""; ""color1"", iferror(choose(match(F10"&", {0, M10:P10}), ""#2FCFC2"", ""#B9F2FF"", ""#85FA85"", ""#EC44CA"", ""#fbc2ea"" )) } ) "),"") | M10: =IFERROR(__xludf.DUMMYFUNCTION("""COMPUTED_VALUE"""),2800.0) -> 2800 | N10: =IFERROR(__xludf.DUMMYFUNCTION("""COMPUTED_VALUE"""),3175.0) -> 3175 | O10: =IFERROR(__xludf.DUMMYFUNCTION("""COMPUTED_VALUE"""),3500.0) -> 3500 | P10: =IFERROR(__xludf.DUMMYFUNCTION("""COMPUTED_VALUE"""),3750.0) -> 3750
B11: Reactive | C11: =IFERROR(__xludf.DUMMYFUNCTION("""COMPUTED_VALUE""")," VT Aether Intermediate S5") -> VT Aether Intermediate S5 | F11: 2465 | G11: =IFERROR(__xludf.DUMMYFUNCTION("sparkline( F11 - choose(match(F11, {0, M11:P11}), 0, M11, N11, O11, P11), { ""charttype"", ""bar""; ""max"", choose(match(F11, {0, M11:P11}), M11, N11-M11, O11-N11, P11-O11, 0); ""nan"", ""ignore""; ""color1"", iferror(choose(match(F11"&", {0, M11:P11}), ""#2FCFC2"", ""#B9F2FF"", ""#85FA85"", ""#EC44CA"", ""#fbc2ea"" )) } ) "),"") | H11: {=trunc(min(Advanced!M$2, max( choose(match(F11, {0, M11-(N11-M11), M11:P11}), 0, Novice!P$2, M$2, N$2, O$2, P$2) + (F11 - choose(match(F11, {0, M11-(N11-M11), M11:P11}), 0, M11-(N11-M11), M11, N11, O11, P11)) / choose(match(F11, {0, M11-(N11-M11), M11:P11}), M11-(N11-M11), N11-M11, N11-M11, O11-N11, P11-O11, P11-O11) * choose(match(F11, {0, M11-(N11-M11), M11:P11}), Novice!P$2, M$2-Novice!P$2, N$2-M$2, O$2-N$2, P$2-O$2, P$2-O$2), choose(match(F12, {0, M12-(N12-M12), M12:P12}), 0, Novice!P$2, M$2, N$2, O$2, P$2) + (F12 - choose(match(F12, {0, M12-(N12-M12), M12:P12}), 0, M12-(N12-M12), M12, N12, O12, P12)) / choose(match(F12, {0, M12-(N12-M12), M12:P12}), M12-(N12-M12), N12-M12, N12-M12, O12-N12, P12-O12, P12-O12) * choose(match(F12, {0, M12-(N12-M12), M12:P12}), Novice!P$2, M$2-Novice!P$2, N$2-M$2, O$2-N$2, P$2-O$2, P$2-O$2) )))} -> 626 | M11: =IFERROR(__xludf.DUMMYFUNCTION("""COMPUTED_VALUE"""),2175.0) -> 2175 | N11: =IFERROR(__xludf.DUMMYFUNCTION("""COMPUTED_VALUE"""),2550.0) -> 2550 | O11: =IFERROR(__xludf.DUMMYFUNCTION("""COMPUTED_VALUE"""),2900.0) -> 2900 | P11: =IFERROR(__xludf.DUMMYFUNCTION("""COMPUTED_VALUE"""),3175.0) -> 3175
C12: =IFERROR(__xludf.DUMMYFUNCTION("""COMPUTED_VALUE""")," VT Ground Intermediate S5") -> VT Ground Intermediate S5 | F12: 2916 | G12: =IFERROR(__xludf.DUMMYFUNCTION("sparkline( F12 - choose(match(F12, {0, M12:P12}), 0, M12, N12, O12, P12), { ""charttype"", ""bar""; ""max"", choose(match(F12, {0, M12:P12}), M12, N12-M12, O12-N12, P12-O12, 0); ""nan"", ""ignore""; ""color1"", iferror(choose(match(F12"&", {0, M12:P12}), ""#2FCFC2"", ""#B9F2FF"", ""#85FA85"", ""#EC44CA"", ""#fbc2ea"" )) } ) "),"") | M12: =IFERROR(__xludf.DUMMYFUNCTION("""COMPUTED_VALUE"""),2550.0) -> 2550 | N12: =IFERROR(__xludf.DUMMYFUNCTION("""COMPUTED_VALUE"""),2850.0) -> 2850 | O12: =IFERROR(__xludf.DUMMYFUNCTION("""COMPUTED_VALUE"""),3100.0) -> 3100 | P12: =IFERROR(__xludf.DUMMYFUNCTION("""COMPUTED_VALUE"""),3350.0) -> 3350
B13: Control | C13: =IFERROR(__xludf.DUMMYFUNCTION("""COMPUTED_VALUE""")," VT Raw Control Intermediate S5") -> VT Raw Control Intermediate S5 | F13: 2698 | G13: =IFERROR(__xludf.DUMMYFUNCTION("sparkline( F13 - choose(match(F13, {0, M13:P13}), 0, M13, N13, O13, P13), { ""charttype"", ""bar""; ""max"", choose(match(F13, {0, M13:P13}), M13, N13-M13, O13-N13, P13-O13, 0); ""nan"", ""ignore""; ""color1"", iferror(choose(match(F13"&", {0, M13:P13}), ""#2FCFC2"", ""#B9F2FF"", ""#85FA85"", ""#EC44CA"", ""#fbc2ea"" )) } ) "),"") | H13: {=trunc(min(Advanced!M$2, max( choose(match(F13, {0, M13-(N13-M13), M13:P13}), 0, Novice!P$2, M$2, N$2, O$2, P$2) + (F13 - choose(match(F13, {0, M13-(N13-M13), M13:P13}), 0, M13-(N13-M13), M13, N13, O13, P13)) / choose(match(F13, {0, M13-(N13-M13), M13:P13}), M13-(N13-M13), N13-M13, N13-M13, O13-N13, P13-O13, P13-O13) * choose(match(F13, {0, M13-(N13-M13), M13:P13}), Novice!P$2, M$2-Novice!P$2, N$2-M$2, O$2-N$2, P$2-O$2, P$2-O$2), choose(match(F14, {0, M14-(N14-M14), M14:P14}), 0, Novice!P$2, M$2, N$2, O$2, P$2) + (F14 - choose(match(F14, {0, M14-(N14-M14), M14:P14}), 0, M14-(N14-M14), M14, N14, O14, P14)) / choose(match(F14, {0, M14-(N14-M14), M14:P14}), M14-(N14-M14), N14-M14, N14-M14, O14-N14, P14-O14, P14-O14) * choose(match(F14, {0, M14-(N14-M14), M14:P14}), Novice!P$2, M$2-Novice!P$2, N$2-M$2, O$2-N$2, P$2-O$2, P$2-O$2) )))} -> 481 | M13: =IFERROR(__xludf.DUMMYFUNCTION("""COMPUTED_VALUE"""),2775.0) -> 2775 | N13: =IFERROR(__xludf.DUMMYFUNCTION("""COMPUTED_VALUE"""),3200.0) -> 3200 | O13: =IFERROR(__xludf.DUMMYFUNCTION("""COMPUTED_VALUE"""),3550.0) -> 3550 | P13: =IFERROR(__xludf.DUMMYFUNCTION("""COMPUTED_VALUE"""),3875.0) -> 3875
C14: =IFERROR(__xludf.DUMMYFUNCTION("""COMPUTED_VALUE""")," VT Controlsphere Intermediate S5") -> VT Controlsphere Intermediate S5 | F14: 2614 | G14: =IFERROR(__xludf.DUMMYFUNCTION("sparkline( F14 - choose(match(F14, {0, M14:P14}), 0, M14, N14, O14, P14), { ""charttype"", ""bar""; ""max"", choose(match(F14, {0, M14:P14}), M14, N14-M14, O14-N14, P14-O14, 0); ""nan"", ""ignore""; ""color1"", iferror(choose(match(F14"&", {0, M14:P14}), ""#2FCFC2"", ""#B9F2FF"", ""#85FA85"", ""#EC44CA"", ""#fbc2ea"" )) } ) "),"") | M14: =IFERROR(__xludf.DUMMYFUNCTION("""COMPUTED_VALUE"""),2750.0) -> 2750 | N14: =IFERROR(__xludf.DUMMYFUNCTION("""COMPUTED_VALUE"""),3175.0) -> 3175 | O14: =IFERROR(__xludf.DUMMYFUNCTION("""COMPUTED_VALUE"""),3525.0) -> 3525 | P14: =IFERROR(__xludf.DUMMYFUNCTION("""COMPUTED_VALUE"""),3825.0) -> 3825
A15: Switching | B15: Speed | C15: =IFERROR(__xludf.DUMMYFUNCTION("""COMPUTED_VALUE""")," VT DotTS Intermediate S5") -> VT DotTS Intermediate S5 | F15: 1177 | G15: =IFERROR(__xludf.DUMMYFUNCTION("sparkline( F15 - choose(match(F15, {0, M15:P15}), 0, M15, N15, O15, P15), { ""charttype"", ""bar""; ""max"", choose(match(F15, {0, M15:P15}), M15, N15-M15, O15-N15, P15-O15, 0); ""nan"", ""ignore""; ""color1"", iferror(choose(match(F15"&", {0, M15:P15}), ""#2FCFC2"", ""#B9F2FF"", ""#85FA85"", ""#EC44CA"", ""#fbc2ea"" )) } ) "),"") | H15: {=trunc(min(Advanced!M$2, max( choose(match(F15, {0, M15-(N15-M15), M15:P15}), 0, Novice!P$2, M$2, N$2, O$2, P$2) + (F15 - choose(match(F15, {0, M15-(N15-M15), M15:P15}), 0, M15-(N15-M15), M15, N15, O15, P15)) / choose(match(F15, {0, M15-(N15-M15), M15:P15}), M15-(N15-M15), N15-M15, N15-M15, O15-N15, P15-O15, P15-O15) * choose(match(F15, {0, M15-(N15-M15), M15:P15}), Novice!P$2, M$2-Novice!P$2, N$2-M$2, O$2-N$2, P$2-O$2, P$2-O$2), choose(match(F16, {0, M16-(N16-M16), M16:P16}), 0, Novice!P$2, M$2, N$2, O$2, P$2) + (F16 - choose(match(F16, {0, M16-(N16-M16), M16:P16}), 0, M16-(N16-M16), M16, N16, O16, P16)) / choose(match(F16, {0, M16-(N16-M16), M16:P16}), M16-(N16-M16), N16-M16, N16-M16, O16-N16, P16-O16, P16-O16) * choose(match(F16, {0, M16-(N16-M16), M16:P16}), Novice!P$2, M$2-Novice!P$2, N$2-M$2, O$2-N$2, P$2-O$2, P$2-O$2) )))} -> 595 | M15: =IFERROR(__xludf.DUMMYFUNCTION("""COMPUTED_VALUE"""),1110.0) -> 1110 | N15: =IFERROR(__xludf.DUMMYFUNCTION("""COMPUTED_VALUE"""),1180.0) -> 1180 | O15: =IFERROR(__xludf.DUMMYFUNCTION("""COMPUTED_VALUE"""),1230.0) -> 1230 | P15: =IFERROR(__xludf.DUMMYFUNCTION("""COMPUTED_VALUE"""),1280.0) -> 1280
C16: =IFERROR(__xludf.DUMMYFUNCTION("""COMPUTED_VALUE""")," VT EddieTS Intermediate S5") -> VT EddieTS Intermediate S5 | F16: 896 | G16: =IFERROR(__xludf.DUMMYFUNCTION("sparkline( F16 - choose(match(F16, {0, M16:P16}), 0, M16, N16, O16, P16), { ""charttype"", ""bar""; ""max"", choose(match(F16, {0, M16:P16}), M16, N16-M16, O16-N16, P16-O16, 0); ""nan"", ""ignore""; ""color1"", iferror(choose(match(F16"&", {0, M16:P16}), ""#2FCFC2"", ""#B9F2FF"", ""#85FA85"", ""#EC44CA"", ""#fbc2ea"" )) } ) "),"") | M16: =IFERROR(__xludf.DUMMYFUNCTION("""COMPUTED_VALUE"""),880.0) -> 880 | N16: =IFERROR(__xludf.DUMMYFUNCTION("""COMPUTED_VALUE"""),950.0) -> 950 | O16: =IFERROR(__xludf.DUMMYFUNCTION("""COMPUTED_VALUE"""),1020.0) -> 1020 | P16: =IFERROR(__xludf.DUMMYFUNCTION("""COMPUTED_VALUE"""),1080.0) -> 1080
B17: Evasive | C17: =IFERROR(__xludf.DUMMYFUNCTION("""COMPUTED_VALUE""")," VT DriftTS Intermediate S5") -> VT DriftTS Intermediate S5 | F17: 380 | G17: =IFERROR(__xludf.DUMMYFUNCTION("sparkline( F17 - choose(match(F17, {0, M17:P17}), 0, M17, N17, O17, P17), { ""charttype"", ""bar""; ""max"", choose(match(F17, {0, M17:P17}), M17, N17-M17, O17-N17, P17-O17, 0); ""nan"", ""ignore""; ""color1"", iferror(choose(match(F17"&", {0, M17:P17}), ""#2FCFC2"", ""#B9F2FF"", ""#85FA85"", ""#EC44CA"", ""#fbc2ea"" )) } ) "),"") | H17: {=trunc(min(Advanced!M$2, max( choose(match(F17, {0, M17-(N17-M17), M17:P17}), 0, Novice!P$2, M$2, N$2, O$2, P$2) + (F17 - choose(match(F17, {0, M17-(N17-M17), M17:P17}), 0, M17-(N17-M17), M17, N17, O17, P17)) / choose(match(F17, {0, M17-(N17-M17), M17:P17}), M17-(N17-M17), N17-M17, N17-M17, O17-N17, P17-O17, P17-O17) * choose(match(F17, {0, M17-(N17-M17), M17:P17}), Novice!P$2, M$2-Novice!P$2, N$2-M$2, O$2-N$2, P$2-O$2, P$2-O$2), choose(match(F18, {0, M18-(N18-M18), M18:P18}), 0, Novice!P$2, M$2, N$2, O$2, P$2) + (F18 - choose(match(F18, {0, M18-(N18-M18), M18:P18}), 0, M18-(N18-M18), M18, N18, O18, P18)) / choose(match(F18, {0, M18-(N18-M18), M18:P18}), M18-(N18-M18), N18-M18, N18-M18, O18-N18, P18-O18, P18-O18) * choose(match(F18, {0, M18-(N18-M18), M18:P18}), Novice!P$2, M$2-Novice!P$2, N$2-M$2, O$2-N$2, P$2-O$2, P$2-O$2) )))} -> 617 | M17: =IFERROR(__xludf.DUMMYFUNCTION("""COMPUTED_VALUE"""),390.0) -> 390 | N17: =IFERROR(__xludf.DUMMYFUNCTION("""COMPUTED_VALUE"""),430.0) -> 430 | O17: =IFERROR(__xludf.DUMMYFUNCTION("""COMPUTED_VALUE"""),460.0) -> 460 | P17: =IFERROR(__xludf.DUMMYFUNCTION("""COMPUTED_VALUE"""),490.0) -> 490
C18: =IFERROR(__xludf.DUMMYFUNCTION("""COMPUTED_VALUE""")," VT FlyTS Intermediate S5") -> VT FlyTS Intermediate S5 | F18: 577 | G18: =IFERROR(__xludf.DUMMYFUNCTION("sparkline( F18 - choose(match(F18, {0, M18:P18}), 0, M18, N18, O18, P18), { ""charttype"", ""bar""; ""max"", choose(match(F18, {0, M18:P18}), M18, N18-M18, O18-N18, P18-O18, 0); ""nan"", ""ignore""; ""color1"", iferror(choose(match(F18"&", {0, M18:P18}), ""#2FCFC2"", ""#B9F2FF"", ""#85FA85"", ""#EC44CA"", ""#fbc2ea"" )) } ) "),"") | M18: =IFERROR(__xludf.DUMMYFUNCTION("""COMPUTED_VALUE"""),520.0) -> 520 | N18: =IFERROR(__xludf.DUMMYFUNCTION("""COMPUTED_VALUE"""),570.0) -> 570 | O18: =IFERROR(__xludf.DUMMYFUNCTION("""COMPUTED_VALUE"""),610.0) -> 610 | P18: =IFERROR(__xludf.DUMMYFUNCTION("""COMPUTED_VALUE"""),650.0) -> 650
B19: Stability | C19: =IFERROR(__xludf.DUMMYFUNCTION("""COMPUTED_VALUE""")," VT ControlTS Intermediate S5") -> VT ControlTS Intermediate S5 | F19: 420 | G19: =IFERROR(__xludf.DUMMYFUNCTION("sparkline( F19 - choose(match(F19, {0, M19:P19}), 0, M19, N19, O19, P19), { ""charttype"", ""bar""; ""max"", choose(match(F19, {0, M19:P19}), M19, N19-M19, O19-N19, P19-O19, 0); ""nan"", ""ignore""; ""color1"", iferror(choose(match(F19"&", {0, M19:P19}), ""#2FCFC2"", ""#B9F2FF"", ""#85FA85"", ""#EC44CA"", ""#fbc2ea"" )) } ) "),"") | H19: {=trunc(min(Advanced!M$2, max( choose(match(F19, {0, M19-(N19-M19), M19:P19}), 0, Novice!P$2, M$2, N$2, O$2, P$2) + (F19 - choose(match(F19, {0, M19-(N19-M19), M19:P19}), 0, M19-(N19-M19), M19, N19, O19, P19)) / choose(match(F19, {0, M19-(N19-M19), M19:P19}), M19-(N19-M19), N19-M19, N19-M19, O19-N19, P19-O19, P19-O19) * choose(match(F19, {0, M19-(N19-M19), M19:P19}), Novice!P$2, M$2-Novice!P$2, N$2-M$2, O$2-N$2, P$2-O$2, P$2-O$2), choose(match(F20, {0, M20-(N20-M20), M20:P20}), 0, Novice!P$2, M$2, N$2, O$2, P$2) + (F20 - choose(match(F20, {0, M20-(N20-M20), M20:P20}), 0, M20-(N20-M20), M20, N20, O20, P20)) / choose(match(F20, {0, M20-(N20-M20), M20:P20}), M20-(N20-M20), N20-M20, N20-M20, O20-N20, P20-O20, P20-O20) * choose(match(F20, {0, M20-(N20-M20), M20:P20}), Novice!P$2, M$2-Novice!P$2, N$2-M$2, O$2-N$2, P$2-O$2, P$2-O$2) )))} -> 575 | M19: =IFERROR(__xludf.DUMMYFUNCTION("""COMPUTED_VALUE"""),420.0) -> 420 | N19: =IFERROR(__xludf.DUMMYFUNCTION("""COMPUTED_VALUE"""),460.0) -> 460 | O19: =IFERROR(__xludf.DUMMYFUNCTION("""COMPUTED_VALUE"""),485.0) -> 485 | P19: =IFERROR(__xludf.DUMMYFUNCTION("""COMPUTED_VALUE"""),520.0) -> 520
C20: =IFERROR(__xludf.DUMMYFUNCTION("""COMPUTED_VALUE""")," VT Penta Bounce Intermediate S5") -> VT Penta Bounce Intermediate S5 | F20: 480 | G20: =IFERROR(__xludf.DUMMYFUNCTION("sparkline( F20 - choose(match(F20, {0, M20:P20}), 0, M20, N20, O20, P20), { ""charttype"", ""bar""; ""max"", choose(match(F20, {0, M20:P20}), M20, N20-M20, O20-N20, P20-O20, 0); ""nan"", ""ignore""; ""color1"", iferror(choose(match(F20"&", {0, M20:P20}), ""#2FCFC2"", ""#B9F2FF"", ""#85FA85"", ""#EC44CA"", ""#fbc2ea"" )) } ) "),"") | M20: =IFERROR(__xludf.DUMMYFUNCTION("""COMPUTED_VALUE"""),450.0) -> 450 | N20: =IFERROR(__xludf.DUMMYFUNCTION("""COMPUTED_VALUE"""),490.0) -> 490 | O20: =IFERROR(__xludf.DUMMYFUNCTION("""COMPUTED_VALUE"""),540.0) -> 540 | P20: =IFERROR(__xludf.DUMMYFUNCTION("""COMPUTED_VALUE"""),580.0) -> 580
A21: Sharecode | G21: =IFERROR(__xludf.DUMMYFUNCTION("if(importrange(""https://docs.google.com/spreadsheets/d/1JxRnDKurkxZO94D2V46kmGWozPF7dbOpsMfWZL85LvU"", ""Changelog!A2:A2"")=indirect(""Changelog!A2""), concatenate(""Sheet Version: "", Changelog!A2), hyperlink(""https://docs.google.com/spreadsheets/d/1Jx"&"RnDKurkxZO94D2V46kmGWozPF7dbOpsMfWZL85LvU"", ""Outdated version, click link & make a new copy!""))"),"Sheet Version: 1.0.7") -> Sheet Version: 1.0.7 | N21: =HYPERLINK("https://voltaic.gg/", "Website↗") -> Website↗ | O21: =HYPERLINK("http://discord.gg/voltaic","Discord↗") -> Discord↗ | P21: =HYPERLINK("http://twitter.com/voltaichq","Twitter↗") -> Twitter↗
A22: KovaaKsBottingShinyDoor
A23: Find more resources in discord.gg/voltaic | N23: =HYPERLINK("https://www.youtube.com/voltaichq","YouTube↗") -> YouTube↗ | O23: =HYPERLINK("https://bit.ly/VTxKvKsGuide","Guide↗") -> Guide↗ | P23: =HYPERLINK("https://docs.google.com/document/d/1omExq_y4ld9vkvbTFkLdjlT5UwQpvYSgyk5PgA7nrzM/edit?usp=sharing","Rules↗") -> Rules↗

Sheet Advanced
A1: Voltaic KvKs Advanced Benchmarks S5 BETA | E1: {=concatenate(choose(match(H2, {0, M2:P2}), "Unranked", M1, N1, O1, P1), if(and(F3:F20 >= choose(match(H2, {0, M2:P2}), 1E+99, M3:M20, N3:N20, O3:O20, P3:P20)), " Complete", ""))} -> Unranked | H1: Energy | I1: {=concatenate(choose(match(M2, {0, N2:Q2}), "Unranked", N1, O1, P1, Q1), if(and(J3:J18 >= choose(match(H2, {0, N2:Q2}), 1E+99, N3:N18, O3:O18, P3:P18, Q3:Q18)), " Complete", ""))} -> Unranked | M1: =IFERROR(__xludf.DUMMYFUNCTION("importrange(""https://docs.google.com/spreadsheets/d/1JxRnDKurkxZO94D2V46kmGWozPF7dbOpsMfWZL85LvU"", ""Advanced!M1:P20"")"),"Grandmaster") -> Grandmaster | N1: =IFERROR(__xludf.DUMMYFUNCTION("""COMPUTED_VALUE"""),"Nova") -> Nova | O1: =IFERROR(__xludf.DUMMYFUNCTION("""COMPUTED_VALUE"""),"Astra") -> Astra | P1: =IFERROR(__xludf.DUMMYFUNCTION("""COMPUTED_VALUE"""),"Celestial") -> Celestial
C2: Scenario | F2: High Score | G2: Progress | H2: =iferror(trunc(harmean(H3:H20)), 0) -> 0 | J2: Avg Score | K2: Progress | M2: =IFERROR(__xludf.DUMMYFUNCTION("""COMPUTED_VALUE"""),900.0) -> 900 | N2: =IFERROR(__xludf.DUMMYFUNCTION("""COMPUTED_VALUE"""),1000.0) -> 1000 | O2: =IFERROR(__xludf.DUMMYFUNCTION("""COMPUTED_VALUE"""),1100.0) -> 1100 | P2: =IFERROR(__xludf.DUMMYFUNCTION("""COMPUTED_VALUE"""),1200.0) -> 1200
A3: Clicking | B3: Dynamic | C3: =IFERROR(__xludf.DUMMYFUNCTION("importrange(""https://docs.google.com/spreadsheets/d/1JxRnDKurkxZO94D2V46kmGWozPF7dbOpsMfWZL85LvU"", ""Advanced!C3:C20"")")," VT Pasu Advanced S5") -> VT Pasu Advanced S5 | G3: =IFERROR(__xludf.DUMMYFUNCTION("sparkline( F3 - choose(match(F3, {0, M3:P3}), 0, M3, N3, O3, P3), { ""charttype"", ""bar""; ""max"", choose(match(F3, {0, M3:P3}), M3, N3-M3, O3-N3, P3-O3, 0); ""nan"", ""ignore""; ""color1"", iferror(choose(match(F3, {0, M3:P3}), "&" ""#ffd700"", ""#7900ff"", ""#ff2262"", ""#3d3d3d"", ""#aaaaaa"" )) } ) "),"") | H3: {=trunc(min(1200, max( choose(match(F3, {0, M3-(N3-M3), M3:P3}), 0, Intermediate!P$2, M$2, N$2, O$2, P$2) + (F3 - choose(match(F3, {0, M3-(N3-M3), M3:P3}), 0, M3-(N3-M3), M3, N3, O3, P3)) / choose(match(F3, {0, M3-(N3-M3), M3:P3}), M3-(N3-M3), N3-M3, N3-M3, O3-N3, P3-O3, P3-O3) * choose(match(F3, {0, M3-(N3-M3), M3:P3}), Intermediate!P$2, M$2-Intermediate!P$2, N$2-M$2, O$2-N$2, P$2-O$2, P$2-O$2), choose(match(F4, {0, M4-(N4-M4), M4:P4}), 0, Intermediate!P$2, M$2, N$2, O$2, P$2) + (F4 - choose(match(F4, {0, M4-(N4-M4), M4:P4}), 0, M4-(N4-M4), M4, N4, O4, P4)) / choose(match(F4, {0, M4-(N4-M4), M4:P4}), M4-(N4-M4), N4-M4, N4-M4, O4-N4, P4-O4, P4-O4) * choose(match(F4, {0, M4-(N4-M4), M4:P4}), Intermediate!P$2, M$2-Intermediate!P$2, N$2-M$2, O$2-N$2, P$2-O$2, P$2-O$2) )))} -> 0 | M3: =IFERROR(__xludf.DUMMYFUNCTION("""COMPUTED_VALUE"""),910.0) -> 910 | N3: =IFERROR(__xludf.DUMMYFUNCTION("""COMPUTED_VALUE"""),1020.0) -> 1020 | O3: =IFERROR(__xludf.DUMMYFUNCTION("""COMPUTED_VALUE"""),1110.0) -> 1110 | P3: =IFERROR(__xludf.DUMMYFUNCTION("""COMPUTED_VALUE"""),1240.0) -> 1240
C4: =IFERROR(__xludf.DUMMYFUNCTION("""COMPUTED_VALUE""")," VT Popcorn Advanced S5") -> VT Popcorn Advanced S5 | G4: =IFERROR(__xludf.DUMMYFUNCTION("sparkline( F4 - choose(match(F4, {0, M4:P4}), 0, M4, N4, O4, P4), { ""charttype"", ""bar""; ""max"", choose(match(F4, {0, M4:P4}), M4, N4-M4, O4-N4, P4-O4, 0); ""nan"", ""ignore""; ""color1"", iferror(choose(match(F4, {0, M4:P4}), "&" ""#ffd700"", ""#7900ff"", ""#ff2262"", ""#3d3d3d"", ""#aaaaaa"" )) } ) "),"") | M4: =IFERROR(__xludf.DUMMYFUNCTION("""COMPUTED_VALUE"""),680.0) -> 680 | N4: =IFERROR(__xludf.DUMMYFUNCTION("""COMPUTED_VALUE"""),800.0) -> 800 | O4: =IFERROR(__xludf.DUMMYFUNCTION("""COMPUTED_VALUE"""),910.0) -> 910 | P4: =IFERROR(__xludf.DUMMYFUNCTION("""COMPUTED_VALUE"""),1020.0) -> 1020
B5: Static | C5: =IFERROR(__xludf.DUMMYFUNCTION("""COMPUTED_VALUE""")," VT 1w2ts Advanced S5") -> VT 1w2ts Advanced S5 | G5: =IFERROR(__xludf.DUMMYFUNCTION("sparkline( F5 - choose(match(F5, {0, M5:P5}), 0, M5, N5, O5, P5), { ""charttype"", ""bar""; ""max"", choose(match(F5, {0, M5:P5}), M5, N5-M5, O5-N5, P5-O5, 0); ""nan"", ""ignore""; ""color1"", iferror(choose(match(F5, {0, M5:P5}), "&" ""#ffd700"", ""#7900ff"", ""#ff2262"", ""#3d3d3d"", ""#aaaaaa"" )) } ) "),"") | H5: {=trunc(min(1200, max( choose(match(F5, {0, M5-(N5-M5), M5:P5}), 0, Intermediate!P$2, M$2, N$2, O$2, P$2) + (F5 - choose(match(F5, {0, M5-(N5-M5), M5:P5}), 0, M5-(N5-M5), M5, N5, O5, P5)) / choose(match(F5, {0, M5-(N5-M5), M5:P5}), M5-(N5-M5), N5-M5, N5-M5, O5-N5, P5-O5, P5-O5) * choose(match(F5, {0, M5-(N5-M5), M5:P5}), Intermediate!P$2, M$2-Intermediate!P$2, N$2-M$2, O$2-N$2, P$2-O$2, P$2-O$2), choose(match(F6, {0, M6-(N6-M6), M6:P6}), 0, Intermediate!P$2, M$2, N$2, O$2, P$2) + (F6 - choose(match(F6, {0, M6-(N6-M6), M6:P6}), 0, M6-(N6-M6), M6, N6, O6, P6)) / choose(match(F6, {0, M6-(N6-M6), M6:P6}), M6-(N6-M6), N6-M6, N6-M6, O6-N6, P6-O6, P6-O6) * choose(match(F6, {0, M6-(N6-M6), M6:P6}), Intermediate!P$2, M$2-Intermediate!P$2, N$2-M$2, O$2-N$2, P$2-O$2, P$2-O$2) )))} -> 0 | M5: =IFERROR(__xludf.DUMMYFUNCTION("""COMPUTED_VALUE"""),1320.0) -> 1320 | N5: =IFERROR(__xludf.DUMMYFUNCTION("""COMPUTED_VALUE"""),1420.0) -> 1420 | O5: =IFERROR(__xludf.DUMMYFUNCTION("""COMPUTED_VALUE"""),1520.0) -> 1520 | P5: =IFERROR(__xludf.DUMMYFUNCTION("""COMPUTED_VALUE"""),1620.0) -> 1620
C6: =IFERROR(__xludf.DUMMYFUNCTION("""COMPUTED_VALUE""")," VT ww5t Advanced S5") -> VT ww5t Advanced S5 | G6: =IFERROR(__xludf.DUMMYFUNCTION("sparkline( F6 - choose(match(F6, {0, M6:P6}), 0, M6, N6, O6, P6), { ""charttype"", ""bar""; ""max"", choose(match(F6, {0, M6:P6}), M6, N6-M6, O6-N6, P6-O6, 0); ""nan"", ""ignore""; ""color1"", iferror(choose(match(F6, {0, M6:P6}), "&" ""#ffd700"", ""#7900ff"", ""#ff2262"", ""#3d3d3d"", ""#aaaaaa"" )) } ) "),"") | M6: =IFERROR(__xludf.DUMMYFUNCTION("""COMPUTED_VALUE"""),1510.0) -> 1510 | N6: =IFERROR(__xludf.DUMMYFUNCTION("""COMPUTED_VALUE"""),1610.0) -> 1610 | O6: =IFERROR(__xludf.DUMMYFUNCTION("""COMPUTED_VALUE"""),1720.0) -> 1720 | P6: =IFERROR(__xludf.DUMMYFUNCTION("""COMPUTED_VALUE"""),1860.0) -> 1860
B7: Linear | C7: =IFERROR(__xludf.DUMMYFUNCTION("""COMPUTED_VALUE""")," VT Frogtagon Advanced S5") -> VT Frogtagon Advanced S5 | G7: =IFERROR(__xludf.DUMMYFUNCTION("sparkline( F7 - choose(match(F7, {0, M7:P7}), 0, M7, N7, O7, P7), { ""charttype"", ""bar""; ""max"", choose(match(F7, {0, M7:P7}), M7, N7-M7, O7-N7, P7-O7, 0); ""nan"", ""ignore""; ""color1"", iferror(choose(match(F7, {0, M7:P7}), "&" ""#ffd700"", ""#7900ff"", ""#ff2262"", ""#3d3d3d"", ""#aaaaaa"" )) } ) "),"") | H7: {=trunc(min(1200, max( choose(match(F7, {0, M7-(N7-M7), M7:P7}), 0, Intermediate!P$2, M$2, N$2, O$2, P$2) + (F7 - choose(match(F7, {0, M7-(N7-M7), M7:P7}), 0, M7-(N7-M7), M7, N7, O7, P7)) / choose(match(F7, {0, M7-(N7-M7), M7:P7}), M7-(N7-M7), N7-M7, N7-M7, O7-N7, P7-O7, P7-O7) * choose(match(F7, {0, M7-(N7-M7), M7:P7}), Intermediate!P$2, M$2-Intermediate!P$2, N$2-M$2, O$2-N$2, P$2-O$2, P$2-O$2), choose(match(F8, {0, M8-(N8-M8), M8:P8}), 0, Intermediate!P$2, M$2, N$2, O$2, P$2) + (F8 - choose(match(F8, {0, M8-(N8-M8), M8:P8}), 0, M8-(N8-M8), M8, N8, O8, P8)) / choose(match(F8, {0, M8-(N8-M8), M8:P8}), M8-(N8-M8), N8-M8, N8-M8, O8-N8, P8-O8, P8-O8) * choose(match(F8, {0, M8-(N8-M8), M8:P8}), Intermediate!P$2, M$2-Intermediate!P$2, N$2-M$2, O$2-N$2, P$2-O$2, P$2-O$2) )))} -> 0 | M7: =IFERROR(__xludf.DUMMYFUNCTION("""COMPUTED_VALUE"""),1090.0) -> 1090 | N7: =IFERROR(__xludf.DUMMYFUNCTION("""COMPUTED_VALUE"""),1220.0) -> 1220 | O7: =IFERROR(__xludf.DUMMYFUNCTION("""COMPUTED_VALUE"""),1360.0) -> 1360 | P7: =IFERROR(__xludf.DUMMYFUNCTION("""COMPUTED_VALUE"""),1490.0) -> 1490
C8: =IFERROR(__xludf.DUMMYFUNCTION("""COMPUTED_VALUE""")," VT Floating Heads Advanced S5") -> VT Floating Heads Advanced S5 | G8: =IFERROR(__xludf.DUMMYFUNCTION("sparkline( F8 - choose(match(F8, {0, M8:P8}), 0, M8, N8, O8, P8), { ""charttype"", ""bar""; ""max"", choose(match(F8, {0, M8:P8}), M8, N8-M8, O8-N8, P8-O8, 0); ""nan"", ""ignore""; ""color1"", iferror(choose(match(F8, {0, M8:P8}), "&" ""#ffd700"", ""#7900ff"", ""#ff2262"", ""#3d3d3d"", ""#aaaaaa"" )) } ) "),"") | M8: =IFERROR(__xludf.DUMMYFUNCTION("""COMPUTED_VALUE"""),740.0) -> 740 | N8: =IFERROR(__xludf.DUMMYFUNCTION("""COMPUTED_VALUE"""),830.0) -> 830 | O8: =IFERROR(__xludf.DUMMYFUNCTION("""COMPUTED_VALUE"""),920.0) -> 920 | P8: =IFERROR(__xludf.DUMMYFUNCTION("""COMPUTED_VALUE"""),1050.0) -> 1050
